Workbook

Sheet README
B2: Warehouse Inventory Health, Replenishment & Cost
B3: Novita Fitriyanti Pulungan | Excel portfolio project
B5: Tujuan
B6: Menghitung ulang reorder point dengan safety stock, menemukan item yang perlu dipesan dan yang overstock, menghitung biaya simpan dan trade-off service level, lalu mengelompokkan item dengan matriks ABC-XYZ.
B8: Sumber data
B9: Logistics Warehouse Dataset (Kaggle, ziya07): https://www.kaggle.com/datasets/ziya07/logistics-warehouse-dataset. Dataset publik SINTETIS, 3.204 item, tahun 2024. Satuan mata uang tidak disebutkan di data card.
B11: Alur workbook
B12: DATA (mentah, tidak diubah) -> PARAMETER (asumsi yang bisa diganti) -> PROCESS (kolom hitungan per item, semua rumus) -> ANALYSIS (tabel ringkasan, semua rumus) -> DASHBOARD -> INSIGHT.
B14: Cara pakai
B15: Ganti service level atau ambang ABC/XYZ di sheet PARAMETER (sel kuning, teks biru). Semua angka di PROCESS, ANALYSIS, dan DASHBOARD ikut berubah. Untuk melihat daftar item yang perlu dipesan, filter kolom Status di sheet PROCESS.
B17: Rumus inti
B18: Lead-time demand = demand harian x lead time. Safety stock = z x std dev demand x akar(lead time). ROP = lead-time demand + safety stock. Level maksimum = ROP + demand harian x interval reorder. Status: REORDER kalau stok <= ROP, OVERSTOCK kalau stok > level maksimum, selain itu OK.
... B24: Teks biru dengan latar kuning = input/asumsi yang boleh diganti. Teks hitam = rumus.

Sheet DATA
A1: item_id | B1: category | C1: stock_level | D1: reorder_point | E1: reorder_frequency_days | F1: lead_time_days | G1: daily_demand | H1: demand_std_dev | I1: item_popularity_score | J1: storage_location_id | K1: zone | L1: picking_time_seconds | M1: handling_cost_per_unit | N1: unit_price | O1: holding_cost_per_unit_day | P1: stockout_count_last_month | Q1: order_fulfillment_rate | R1: total_orders_last_month | S1: turnover_ratio | T1: layout_efficiency_score | U1: last_restock_date | V1: forecasted_demand_next_7d | W1: KPI_score
A2: ITM10000 | B2: Pharma | C2: 283 | D2: 21 | E2: 4 | F2: 4 | G2: 49.85 | H2: 1.56 | I2: 0.43 | J2: L82 | K2: B | L2: 106 | M2: 3.61 | N2: 117.8 | O2: 1.14 | P2: 0 | Q2: 0.8 | R2: 700 | S2: 3.33 | T2: 0.33 | U2: 45339 | V2: 184.37 | W2: 0.556
A3: ITM10001 | B3: Automotive | C3: 301 | D3: 52 | E3: 9 | F3: 6 | G3: 23.34 | H3: 2.55 | I3: 0.69 | J3: L15 | K3: A | L3: 45 | M3: 3.54 | N3: 178.8 | O3: 1.09 | P3: 3 | Q3: 0.79 | R3: 736 | S3: 10.36 | T3: 0.98 | U3: 45566 | V3: 221.94 | W3: 0.723
A4: ITM10002 | B4: Groceries | C4: 132 | D4: 60 | E4: 11 | F4: 8 | G4: 37.69 | H4: 3.15 | I4: 0.62 | J4: L4 | K4: B | L4: 177 | M4: 0.52 | N4: 54.05 | O4: 0.95 | P4: 7 | Q4: 0.75 | R4: 814 | S4: 14.32 | T4: 0.87 | U4: 45389 | V4: 53.85 | W4: 0.68
A5: ITM10003 | B5: Automotive | C5: 346 | D5: 46 | E5: 13 | F5: 5 | G5: 33.69 | H5: 2.79 | I5: 0.21 | J5: L95 | K5: A | L5: 39 | M5: 2.64 | N5: 31.1 | O5: 1.9 | P5: 0 | Q5: 0.96 | R5: 994 | S5: 2.08 | T5: 0.29 | U5: 45318 | V5: 92.04 | W5: 0.488
A6: ITM10004 | B6: Automotive | C6: 49 | D6: 55 | E6: 4 | F6: 6 | G6: 49.58 | H6: 5.23 | I6: 0.31 | J6: L36 | K6: D | L6: 35 | M6: 1.4 | N6: 104.97 | O6: 0.63 | P6: 5 | Q6: 0.83 | R6: 299 | S6: 5.65 | T6: 0.96 | U6: 45429 | V6: 194.58 | W6: 0.67
A7: ITM10005 | B7: Apparel | C7: 154 | D7: 62 | E7: 9 | F7: 6 | G7: 35.95 | H7: 9.47 | I7: 0.41 | J7: L32 | K7: A | L7: 94 | M7: 1.96 | N7: 164.12 | O7: 0.66 | P7: 1 | Q7: 0.99 | R7: 477 | S7: 7.61 | T7: 0.95 | U7: 45485 | V7: 180.65 | W7: 0.803
A8: ITM10006 | B8: Groceries | C8: 86 | D8: 97 | E8: 6 | F8: 4 | G8: 9.04 | H8: 4.72 | I8: 0.28 | J8: L29 | K8: C | L8: 110 | M8: 4.9 | N8: 134.38 | O8: 0.37 | P8: 8 | Q8: 0.88 | R8: 418 | S8: 4.25 | T8: 0.45 | U8: 45636 | V8: 223.69 | W8: 0.526
A9: ITM10007 | B9: Groceries | C9: 84 | D9: 89 | E9: 13 | F9: 4 | G9: 47.82 | H9: 6.78 | I9: 0.24 | J9: L18 | K9: D | L9: 130 | M9: 0.88 | N9: 131.09 | O9: 1.42 | P9: 7 | Q9: 0.74 | R9: 958 | S9: 11.37 | T9: 0.7 | U9: 45601 | V9: 195.75 | W9: 0.558
A10: ITM10008 | B10: Groceries | C10: 311 | D10: 22 | E10: 4 | F10: 9 | G10: 33.72 | H10: 7.04 | I10: 0.15 | J10: L95 | K10: D | L10: 40 | M10: 3.75 | N10: 13.32 | O10: 0.71 | P10: 8 | Q10: 0.86 | R10: 697 | S10: 10.64 | T10: 0.29 | U10: 45600 | V10: 105.74 | W10: 0.541
A11: ITM10009 | B11: Automotive | C11: 44 | D11: 98 | E11: 9 | F11: 8 | G11: 3.91 | H11: 8.78 | I11: 0.89 | J11: L14 | K11: A | L11: 26 | M11: 1.28 | N11: 70.32 | O11: 1.63 | P11: 8 | Q11: 1 | R11: 496 | S11: 2.65 | T11: 0.27 | U11: 45312 | V11: 154.78 | W11: 0.366
A12: ITM10010 | B12: Pharma | C12: 56 | D12: 63 | E12: 7 | F12: 2 | G12: 33.22 | H12: 0.82 | I12: 0.36 | J12: L87 | K12: B | L12: 107 | M12: 0.53 | N12: 188.5 | O12: 1.95 | P12: 1 | Q12: 0.87 | R12: 71 | S12: 8.97 | T12: 0.6 | U12: 45329 | V12: 266.58 | W12: 0.599
A13: ITM10011 | B13: Groceries | C13: 20 | D13: 66 | E13: 3 | F13: 7 | G13: 44.27 | H13: 4.34 | I13: 0.36 | J13: L95 | K13: A | L13: 135 | M13: 2.76 | N13: 35.51 | O13: 0.18 | P13: 1 | Q13: 0.7 | R13: 599 | S13: 6.16 | T13: 0.24 | U13: 45388 | V13: 63.97 | W13: 0.632
... A3205: ITM13203 | B3205: Apparel | C3205: 377 | D3205: 40 | E3205: 14 | F3205: 3 | G3205: 29.4 | H3205: 7.43 | I3205: 0.14 | J3205: L48 | K3205: A | L3205: 56 | M3205: 4.92 | N3205: 39.88 | O3205: 1.94 | P3205: 9 | Q3205: 0.92 | R3205: 812 | S3205: 8.74 | T3205: 0.54 | U3205: 45437 | V3205: 193.91 | W3205: 0.435

Sheet PARAMETER
A1: Parameter & asumsi
A2: Parameter | B2: Nilai | C2: Keterangan
A3: Service level target | B3: 0.95 | C3: Peluang stok tidak habis selama lead time. Input.
A4: z (faktor safety stock) | B4: =NORMSINV(B3) -> 1.6448536 | C4: Dihitung dari service level.
A5: Hari per tahun | B5: 365 | C5: Untuk nilai demand tahunan.
A6: Hari per bulan | B6: 30 | C6: Untuk biaya simpan per bulan.
A7: Batas kumulatif kelas A | B7: 0.8 | C7: Item dengan kumulatif nilai tahunan <= 80% = A.
A8: Batas kumulatif kelas B | B8: 0.95 | C8: > 80% sampai 95% = B, sisanya C.
A9: Batas CV kelas X | B9: 0.25 | C9: CV = std dev / demand harian. CV <= 0,25 = X (stabil).
A10: Batas CV kelas Y | B10: 0.5 | C10: CV > 0,25 sampai 0,50 = Y, di atasnya Z (tidak stabil).
A11: Persentil item populer | B11: 0.75 | C11: Item dengan skor popularitas >= persentil ini dianggap paling populer.
A12: Ambang skor populer | B12: =PERCENTILE(DATA!I2:I3205,B11) -> 0.76 | C12: Dihitung dari data.
A13: Ambang picking lambat (median, detik) | B13: =MEDIAN(DATA!L2:L3205) -> 96 | C13: Picking time >= median dianggap lambat.

Sheet PROCESS
A1: item_id | B1: Kategori | C1: Stok | D1: ROP dataset | E1: Lead time (hari) | F1: Demand harian | G1: Std dev demand | H1: Interval reorder (hari) | I1: Lead-time demand | J1: Safety stock | K1: ROP hitung | L1: Level maksimum | M1: Status | N1: Status versi dataset | O1: ROP dataset < lead-time demand | P1: Cover (hari) | Q1: Harga/unit | R1: Biaya simpan/unit/hari | S1: Nilai stok | T1: Biaya simpan/hari | U1: Kelebihan stok (unit) | V1: Nilai kelebihan stok | W1: Biaya simpan kelebihan/hari | X1: Kekurangan vs ROP (unit) | Y1: Nilai demand tahunan | Z1: Kumulatif nilai (%) | AA1: ABC | AB1: CV demand | AC1: XYZ | AD1: ABC-XYZ | AE1: Skor popularitas | AF1: Picking time (detik) | AG1: Zona | AH1: Item populer | AI1: Picking lambat | AJ1: Kandidat pindah lokasi
A2: =DATA!A2 -> ITM10000 | B2: =DATA!B2 -> Pharma | C2: =DATA!C2 -> 283 | D2: =DATA!D2 -> 21 | E2: =DATA!F2 -> 4 | F2: =DATA!G2 -> 49.85 | G2: =DATA!H2 -> 1.56 | H2: =DATA!E2 -> 4 | I2: =F2*E2 -> 199.4 | J2: =PARAMETER!$B$4*G2*SQRT(E2) -> 5.1319433 | K2: =I2+J2 -> 204.53194 | L2: =K2+F2*H2 -> 403.93194 | M2: =IF(C2<=K2,"REORDER",IF(C2>L2,"OVERSTOCK","OK")) -> OK | N2: =IF(C2<=D2,"REORDER","OK") -> OK | O2: =IF(D2<I2,1,0) -> 1 | P2: =C2/F2 -> 5.6770311 | Q2: =DATA!N2 -> 117.8 | R2: =DATA!O2 -> 1.14 | S2: =C2*Q2 -> 33337.4 | T2: =C2*R2 -> 322.62 | U2: =MAX(0,C2-L2) -> 0 | V2: =U2*Q2 -> 0 | W2: =U2*R2 -> 0 | X2: =MAX(0,K2-C2) -> 0 | Y2: =F2*PARAMETER!$B$5*Q2 -> 2143400.5 | Z2: =SUMIF($Y$2:$Y$3205,">="&Y2)/SUM($Y$2:$Y$3205) -> 0.29123606 | AA2: =IF(Z2<=PARAMETER!$B$7,"A",IF(Z2<=PARAMETER!$B$8,"B","C")) -> A | AB2: =G2/F2 -> 0.031293882 | AC2: =IF(AB2<=PARAMETER!$B$9,"X",IF(AB2<=PARAMETER!$B$10,"Y","Z")) -> X | AD2: =AA2&AC2 -> AX | AE2: =DATA!I2 -> 0.43 | AF2: =DATA!L2 -> 106 | AG2: =DATA!K2 -> B | AH2: =IF(AE2>=PARAMETER!$B$12,1,0) -> 0 | AI2: =IF(AF2>=PARAMETER!$B$13,1,0) -> 1 | AJ2: =IF(AND(AH2=1,AI2=1),1,0) -> 0
A3: =DATA!A3 -> ITM10001 | B3: =DATA!B3 -> Automotive | C3: =DATA!C3 -> 301 | D3: =DATA!D3 -> 52 | E3: =DATA!F3 -> 6 | F3: =DATA!G3 -> 23.34 | G3: =DATA!H3 -> 2.55 | H3: =DATA!E3 -> 9 | I3: =F3*E3 -> 140.04 | J3: =PARAMETER!$B$4*G3*SQRT(E3) -> 10.274083 | K3: =I3+J3 -> 150.31408 | L3: =K3+F3*H3 -> 360.37408 | M3: =IF(C3<=K3,"REORDER",IF(C3>L3,"OVERSTOCK","OK")) -> OK | N3: =IF(C3<=D3,"REORDER","OK") -> OK | O3: =IF(D3<I3,1,0) -> 1 | P3: =C3/F3 -> 12.896315 | Q3: =DATA!N3 -> 178.8 | R3: =DATA!O3 -> 1.09 | S3: =C3*Q3 -> 53818.8 | T3: =C3*R3 -> 328.09 | U3: =MAX(0,C3-L3) -> 0 | V3: =U3*Q3 -> 0 | W3: =U3*R3 -> 0 | X3: =MAX(0,K3-C3) -> 0 | Y3: =F3*PARAMETER!$B$5*Q3 -> 1523215.1 | Z3: =SUMIF($Y$2:$Y$3205,">="&Y3)/SUM($Y$2:$Y$3205) -> 0.51416032 | AA3: =IF(Z3<=PARAMETER!$B$7,"A",IF(Z3<=PARAMETER!$B$8,"B","C")) -> A | AB3: =G3/F3 -> 0.1092545 | AC3: =IF(AB3<=PARAMETER!$B$9,"X",IF(AB3<=PARAMETER!$B$10,"Y","Z")) -> X | AD3: =AA3&AC3 -> AX | AE3: =DATA!I3 -> 0.69 | AF3: =DATA!L3 -> 45 | AG3: =DATA!K3 -> A | AH3: =IF(AE3>=PARAMETER!$B$12,1,0) -> 0 | AI3: =IF(AF3>=PARAMETER!$B$13,1,0) -> 0 | AJ3: =IF(AND(AH3=1,AI3=1),1,0) -> 0
A4: =DATA!A4 -> ITM10002 | B4: =DATA!B4 -> Groceries | C4: =DATA!C4 -> 132 | D4: =DATA!D4 -> 60 | E4: =DATA!F4 -> 8 | F4: =DATA!G4 -> 37.69 | G4: =DATA!H4 -> 3.15 | H4: =DATA!E4 -> 11 | I4: =F4*E4 -> 301.52 | J4: =PARAMETER!$B$4*G4*SQRT(E4) -> 14.654898 | K4: =I4+J4 -> 316.1749 | L4: =K4+F4*H4 -> 730.7649 | M4: =IF(C4<=K4,"REORDER",IF(C4>L4,"OVERSTOCK","OK")) -> REORDER | N4: =IF(C4<=D4,"REORDER","OK") -> OK | O4: =IF(D4<I4,1,0) -> 1 | P4: =C4/F4 -> 3.5022552 | Q4: =DATA!N4 -> 54.05 | R4: =DATA!O4 -> 0.95 | S4: =C4*Q4 -> 7134.6 | T4: =C4*R4 -> 125.4 | U4: =MAX(0,C4-L4) -> 0 | V4: =U4*Q4 -> 0 | W4: =U4*R4 -> 0 | X4: =MAX(0,K4-C4) -> 184.1749 | Y4: =F4*PARAMETER!$B$5*Q4 -> 743557.74 | Z4: =SUMIF($Y$2:$Y$3205,">="&Y4)/SUM($Y$2:$Y$3205) -> 0.82935824 | AA4: =IF(Z4<=PARAMETER!$B$7,"A",IF(Z4<=PARAMETER!$B$8,"B","C")) -> B | AB4: =G4/F4 -> 0.083576546 | AC4: =IF(AB4<=PARAMETER!$B$9,"X",IF(AB4<=PARAMETER!$B$10,"Y","Z")) -> X | AD4: =AA4&AC4 -> BX | AE4: =DATA!I4 -> 0.62 | AF4: =DATA!L4 -> 177 | AG4: =DATA!K4 -> B | AH4: =IF(AE4>=PARAMETER!$B$12,1,0) -> 0 | AI4: =IF(AF4>=PARAMETER!$B$13,1,0) -> 1 | AJ4: =IF(AND(AH4=1,AI4=1),1,0) -> 0
A5: =DATA!A5 -> ITM10003 | B5: =DATA!B5 -> Automotive | C5: =DATA!C5 -> 346 | D5: =DATA!D5 -> 46 | E5: =DATA!F5 -> 5 | F5: =DATA!G5 -> 33.69 | G5: =DATA!H5 -> 2.79 | H5: =DATA!E5 -> 13 | I5: =F5*E5 -> 168.45 | J5: =PARAMETER!$B$4*G5*SQRT(E5) -> 10.261633 | K5: =I5+J5 -> 178.71163 | L5: =K5+F5*H5 -> 616.68163 | M5: =IF(C5<=K5,"REORDER",IF(C5>L5,"OVERSTOCK","OK")) -> OK | N5: =IF(C5<=D5,"REORDER","OK") -> OK | O5: =IF(D5<I5,1,0) -> 1 | P5: =C5/F5 -> 10.27011 | Q5: =DATA!N5 -> 31.1 | R5: =DATA!O5 -> 1.9 | S5: =C5*Q5 -> 10760.6 | T5: =C5*R5 -> 657.4 | U5: =MAX(0,C5-L5) -> 0 | V5: =U5*Q5 -> 0 | W5: =U5*R5 -> 0 | X5: =MAX(0,K5-C5) -> 0 | Y5: =F5*PARAMETER!$B$5*Q5 -> 382432.03 | Z5: =SUMIF($Y$2:$Y$3205,">="&Y5)/SUM($Y$2:$Y$3205) -> 0.93853735 | AA5: =IF(Z5<=PARAMETER!$B$7,"A",IF(Z5<=PARAMETER!$B$8,"B","C")) -> B | AB5: =G5/F5 -> 0.082813891 | AC5: =IF(AB5<=PARAMETER!$B$9,"X",IF(AB5<=PARAMETER!$B$10,"Y","Z")) -> X | AD5: =AA5&AC5 -> BX | AE5: =DATA!I5 -> 0.21 | AF5: =DATA!L5 -> 39 | AG5: =DATA!K5 -> A | AH5: =IF(AE5>=PARAMETER!$B$12,1,0) -> 0 | AI5: =IF(AF5>=PARAMETER!$B$13,1,0) -> 0 | AJ5: =IF(AND(AH5=1,AI5=1),1,0) -> 0
A6: =DATA!A6 -> ITM10004 | B6: =DATA!B6 -> Automotive | C6: =DATA!C6 -> 49 | D6: =DATA!D6 -> 55 | E6: =DATA!F6 -> 6 | F6: =DATA!G6 -> 49.58 | G6: =DATA!H6 -> 5.23 | H6: =DATA!E6 -> 4 | I6: =F6*E6 -> 297.48 | J6: =PARAMETER!$B$4*G6*SQRT(E6) -> 21.071942 | K6: =I6+J6 -> 318.55194 | L6: =K6+F6*H6 -> 516.87194 | M6: =IF(C6<=K6,"REORDER",IF(C6>L6,"OVERSTOCK","OK")) -> REORDER | N6: =IF(C6<=D6,"REORDER","OK") -> REORDER | O6: =IF(D6<I6,1,0) -> 1 | P6: =C6/F6 -> 0.98830173 | Q6: =DATA!N6 -> 104.97 | R6: =DATA!O6 -> 0.63 | S6: =C6*Q6 -> 5143.53 | T6: =C6*R6 -> 30.87 | U6: =MAX(0,C6-L6) -> 0 | V6: =U6*Q6 -> 0 | W6: =U6*R6 -> 0 | X6: =MAX(0,K6-C6) -> 269.55194 | Y6: =F6*PARAMETER!$B$5*Q6 -> 1899610.6 | Z6: =SUMIF($Y$2:$Y$3205,">="&Y6)/SUM($Y$2:$Y$3205) -> 0.37445521 | AA6: =IF(Z6<=PARAMETER!$B$7,"A",IF(Z6<=PARAMETER!$B$8,"B","C")) -> A | AB6: =G6/F6 -> 0.10548608 | AC6: =IF(AB6<=PARAMETER!$B$9,"X",IF(AB6<=PARAMETER!$B$10,"Y","Z")) -> X | AD6: =AA6&AC6 -> AX | AE6: =DATA!I6 -> 0.31 | AF6: =DATA!L6 -> 35 | AG6: =DATA!K6 -> D | AH6: =IF(AE6>=PARAMETER!$B$12,1,0) -> 0 | AI6: =IF(AF6>=PARAMETER!$B$13,1,0) -> 0 | AJ6: =IF(AND(AH6=1,AI6=1),1,0) -> 0
A7: =DATA!A7 -> ITM10005 | B7: =DATA!B7 -> Apparel | C7: =DATA!C7 -> 154 | D7: =DATA!D7 -> 62 | E7: =DATA!F7 -> 6 | F7: =DATA!G7 -> 35.95 | G7: =DATA!H7 -> 9.47 | H7: =DATA!E7 -> 9 | I7: =F7*E7 -> 215.7 | J7: =PARAMETER!$B$4*G7*SQRT(E7) -> 38.155123 | K7: =I7+J7 -> 253.85512 | L7: =K7+F7*H7 -> 577.40512 | M7: =IF(C7<=K7,"REORDER",IF(C7>L7,"OVERSTOCK","OK")) -> REORDER | N7: =IF(C7<=D7,"REORDER","OK") -> OK | O7: =IF(D7<I7,1,0) -> 1 | P7: =C7/F7 -> 4.2837274 | Q7: =DATA!N7 -> 164.12 | R7: =DATA!O7 -> 0.66 | S7: =C7*Q7 -> 25274.48 | T7: =C7*R7 -> 101.64 | U7: =MAX(0,C7-L7) -> 0 | V7: =U7*Q7 -> 0 | W7: =U7*R7 -> 0 | X7: =MAX(0,K7-C7) -> 99.855123 | Y7: =F7*PARAMETER!$B$5*Q7 -> 2153541.6 | Z7: =SUMIF($Y$2:$Y$3205,">="&Y7)/SUM($Y$2:$Y$3205) -> 0.28986854 | AA7: =IF(Z7<=PARAMETER!$B$7,"A",IF(Z7<=PARAMETER!$B$8,"B","C")) -> A | AB7: =G7/F7 -> 0.26342142 | AC7: =IF(AB7<=PARAMETER!$B$9,"X",IF(AB7<=PARAMETER!$B$10,"Y","Z")) -> Y | AD7: =AA7&AC7 -> AY | AE7: =DATA!I7 -> 0.41 | AF7: =DATA!L7 -> 94 | AG7: =DATA!K7 -> A | AH7: =IF(AE7>=PARAMETER!$B$12,1,0) -> 0 | AI7: =IF(AF7>=PARAMETER!$B$13,1,0) -> 0 | AJ7: =IF(AND(AH7=1,AI7=1),1,0) -> 0
A8: =DATA!A8 -> ITM10006 | B8: =DATA!B8 -> Groceries | C8: =DATA!C8 -> 86 | D8: =DATA!D8 -> 97 | E8: =DATA!F8 -> 4 | F8: =DATA!G8 -> 9.04 | G8: =DATA!H8 -> 4.72 | H8: =DATA!E8 -> 6 | I8: =F8*E8 -> 36.16 | J8: =PARAMETER!$B$4*G8*SQRT(E8) -> 15.527418 | K8: =I8+J8 -> 51.687418 | L8: =K8+F8*H8 -> 105.92742 | M8: =IF(C8<=K8,"REORDER",IF(C8>L8,"OVERSTOCK","OK")) -> OK | N8: =IF(C8<=D8,"REORDER","OK") -> REORDER | O8: =IF(D8<I8,1,0) -> 0 | P8: =C8/F8 -> 9.5132743 | Q8: =DATA!N8 -> 134.38 | R8: =DATA!O8 -> 0.37 | S8: =C8*Q8 -> 11556.68 | T8: =C8*R8 -> 31.82 | U8: =MAX(0,C8-L8) -> 0 | V8: =U8*Q8 -> 0 | W8: =U8*R8 -> 0 | X8: =MAX(0,K8-C8) -> 0 | Y8: =F8*PARAMETER!$B$5*Q8 -> 443400.25 | Z8: =SUMIF($Y$2:$Y$3205,">="&Y8)/SUM($Y$2:$Y$3205) -> 0.92277427 | AA8: =IF(Z8<=PARAMETER!$B$7,"A",IF(Z8<=PARAMETER!$B$8,"B","C")) -> B | AB8: =G8/F8 -> 0.52212389 | AC8: =IF(AB8<=PARAMETER!$B$9,"X",IF(AB8<=PARAMETER!$B$10,"Y","Z")) -> Z | AD8: =AA8&AC8 -> BZ | AE8: =DATA!I8 -> 0.28 | AF8: =DATA!L8 -> 110 | AG8: =DATA!K8 -> C | AH8: =IF(AE8>=PARAMETER!$B$12,1,0) -> 0 | AI8: =IF(AF8>=PARAMETER!$B$13,1,0) -> 1 | AJ8: =IF(AND(AH8=1,AI8=1),1,0) -> 0
A9: =DATA!A9 -> ITM10007 | B9: =DATA!B9 -> Groceries | C9: =DATA!C9 -> 84 | D9: =DATA!D9 -> 89 | E9: =DATA!F9 -> 4 | F9: =DATA!G9 -> 47.82 | G9: =DATA!H9 -> 6.78 | H9: =DATA!E9 -> 13 | I9: =F9*E9 -> 191.28 | J9: =PARAMETER!$B$4*G9*SQRT(E9) -> 22.304215 | K9: =I9+J9 -> 213.58422 | L9: =K9+F9*H9 -> 835.24422 | M9: =IF(C9<=K9,"REORDER",IF(C9>L9,"OVERSTOCK","OK")) -> REORDER | N9: =IF(C9<=D9,"REORDER","OK") -> REORDER | O9: =IF(D9<I9,1,0) -> 1 | P9: =C9/F9 -> 1.7565872 | Q9: =DATA!N9 -> 131.09 | R9: =DATA!O9 -> 1.42 | S9: =C9*Q9 -> 11011.56 | T9: =C9*R9 -> 119.28 | U9: =MAX(0,C9-L9) -> 0 | V9: =U9*Q9 -> 0 | W9: =U9*R9 -> 0 | X9: =MAX(0,K9-C9) -> 129.58422 | Y9: =F9*PARAMETER!$B$5*Q9 -> 2288084.2 | Z9: =SUMIF($Y$2:$Y$3205,">="&Y9)/SUM($Y$2:$Y$3205) -> 0.24457511 | AA9: =IF(Z9<=PARAMETER!$B$7,"A",IF(Z9<=PARAMETER!$B$8,"B","C")) -> A | AB9: =G9/F9 -> 0.14178168 | AC9: =IF(AB9<=PARAMETER!$B$9,"X",IF(AB9<=PARAMETER!$B$10,"Y","Z")) -> X | AD9: =AA9&AC9 -> AX | AE9: =DATA!I9 -> 0.24 | AF9: =DATA!L9 -> 130 | AG9: =DATA!K9 -> D | AH9: =IF(AE9>=PARAMETER!$B$12,1,0) -> 0 | AI9: =IF(AF9>=PARAMETER!$B$13,1,0) -> 1 | AJ9: =IF(AND(AH9=1,AI9=1),1,0) -> 0
A10: =DATA!A10 -> ITM10008 | B10: =DATA!B10 -> Groceries | C10: =DATA!C10 -> 311 | D10: =DATA!D10 -> 22 | E10: =DATA!F10 -> 9 | F10: =DATA!G10 -> 33.72 | G10: =DATA!H10 -> 7.04 | H10: =DATA!E10 -> 4 | I10: =F10*E10 -> 303.48 | J10: =PARAMETER!$B$4*G10*SQRT(E10) -> 34.739309 | K10: =I10+J10 -> 338.21931 | L10: =K10+F10*H10 -> 473.09931 | M10: =IF(C10<=K10,"REORDER",IF(C10>L10,"OVERSTOCK","OK")) -> REORDER | N10: =IF(C10<=D10,"REORDER","OK") -> OK | O10: =IF(D10<I10,1,0) -> 1 | P10: =C10/F10 -> 9.223013 | Q10: =DATA!N10 -> 13.32 | R10: =DATA!O10 -> 0.71 | S10: =C10*Q10 -> 4142.52 | T10: =C10*R10 -> 220.81 | U10: =MAX(0,C10-L10) -> 0 | V10: =U10*Q10 -> 0 | W10: =U10*R10 -> 0 | X10: =MAX(0,K10-C10) -> 27.219309 | Y10: =F10*PARAMETER!$B$5*Q10 -> 163939.9 | Z10: =SUMIF($Y$2:$Y$3205,">="&Y10)/SUM($Y$2:$Y$3205) -> 0.98875249 | AA10: =IF(Z10<=PARAMETER!$B$7,"A",IF(Z10<=PARAMETER!$B$8,"B","C")) -> C | AB10: =G10/F10 -> 0.20877817 | AC10: =IF(AB10<=PARAMETER!$B$9,"X",IF(AB10<=PARAMETER!$B$10,"Y","Z")) -> X | AD10: =AA10&AC10 -> CX | AE10: =DATA!I10 -> 0.15 | AF10: =DATA!L10 -> 40 | AG10: =DATA!K10 -> D | AH10: =IF(AE10>=PARAMETER!$B$12,1,0) -> 0 | AI10: =IF(AF10>=PARAMETER!$B$13,1,0) -> 0 | AJ10: =IF(AND(AH10=1,AI10=1),1,0) -> 0
A11: =DATA!A11 -> ITM10009 | B11: =DATA!B11 -> Automotive | C11: =DATA!C11 -> 44 | D11: =DATA!D11 -> 98 | E11: =DATA!F11 -> 8 | F11: =DATA!G11 -> 3.91 | G11: =DATA!H11 -> 8.78 | H11: =DATA!E11 -> 9 | I11: =F11*E11 -> 31.28 | J11: =PARAMETER!$B$4*G11*SQRT(E11) -> 40.847621 | K11: =I11+J11 -> 72.127621 | L11: =K11+F11*H11 -> 107.31762 | M11: =IF(C11<=K11,"REORDER",IF(C11>L11,"OVERSTOCK","OK")) -> REORDER | N11: =IF(C11<=D11,"REORDER","OK") -> REORDER | O11: =IF(D11<I11,1,0) -> 0 | P11: =C11/F11 -> 11.253197 | Q11: =DATA!N11 -> 70.32 | R11: =DATA!O11 -> 1.63 | S11: =C11*Q11 -> 3094.08 | T11: =C11*R11 -> 71.72 | U11: =MAX(0,C11-L11) -> 0 | V11: =U11*Q11 -> 0 | W11: =U11*R11 -> 0 | X11: =MAX(0,K11-C11) -> 28.127621 | Y11: =F11*PARAMETER!$B$5*Q11 -> 100357.19 | Z11: =SUMIF($Y$2:$Y$3205,">="&Y11)/SUM($Y$2:$Y$3205) -> 0.99617184 | AA11: =IF(Z11<=PARAMETER!$B$7,"A",IF(Z11<=PARAMETER!$B$8,"B","C")) -> C | AB11: =G11/F11 -> 2.2455243 | AC11: =IF(AB11<=PARAMETER!$B$9,"X",IF(AB11<=PARAMETER!$B$10,"Y","Z")) -> Z | AD11: =AA11&AC11 -> CZ | AE11: =DATA!I11 -> 0.89 | AF11: =DATA!L11 -> 26 | AG11: =DATA!K11 -> A | AH11: =IF(AE11>=PARAMETER!$B$12,1,0) -> 1 | AI11: =IF(AF11>=PARAMETER!$B$13,1,0) -> 0 | AJ11: =IF(AND(AH11=1,AI11=1),1,0) -> 0
A12: =DATA!A12 -> ITM10010 | B12: =DATA!B12 -> Pharma | C12: =DATA!C12 -> 56 | D12: =DATA!D12 -> 63 | E12: =DATA!F12 -> 2 | F12: =DATA!G12 -> 33.22 | G12: =DATA!H12 -> 0.82 | H12: =DATA!E12 -> 7 | I12: =F12*E12 -> 66.44 | J12: =PARAMETER!$B$4*G12*SQRT(E12) -> 1.9074629 | K12: =I12+J12 -> 68.347463 | L12: =K12+F12*H12 -> 300.88746 | M12: =IF(C12<=K12,"REORDER",IF(C12>L12,"OVERSTOCK","OK")) -> REORDER | N12: =IF(C12<=D12,"REORDER","OK") -> REORDER | O12: =IF(D12<I12,1,0) -> 1 | P12: =C12/F12 -> 1.6857315 | Q12: =DATA!N12 -> 188.5 | R12: =DATA!O12 -> 1.95 | S12: =C12*Q12 -> 10556 | T12: =C12*R12 -> 109.2 | U12: =MAX(0,C12-L12) -> 0 | V12: =U12*Q12 -> 0 | W12: =U12*R12 -> 0 | X12: =MAX(0,K12-C12) -> 12.347463 | Y12: =F12*PARAMETER!$B$5*Q12 -> 2285619 | Z12: =SUMIF($Y$2:$Y$3205,">="&Y12)/SUM($Y$2:$Y$3205) -> 0.24749158 | AA12: =IF(Z12<=PARAMETER!$B$7,"A",IF(Z12<=PARAMETER!$B$8,"B","C")) -> A | AB12: =G12/F12 -> 0.024683925 | AC12: =IF(AB12<=PARAMETER!$B$9,"X",IF(AB12<=PARAMETER!$B$10,"Y","Z")) -> X | AD12: =AA12&AC12 -> AX | AE12: =DATA!I12 -> 0.36 | AF12: =DATA!L12 -> 107 | AG12: =DATA!K12 -> B | AH12: =IF(AE12>=PARAMETER!$B$12,1,0) -> 0 | AI12: =IF(AF12>=PARAMETER!$B$13,1,0) -> 1 | AJ12: =IF(AND(AH12=1,AI12=1),1,0) -> 0
A13: =DATA!A13 -> ITM10011 | B13: =DATA!B13 -> Groceries | C13: =DATA!C13 -> 20 | D13: =DATA!D13 -> 66 | E13: =DATA!F13 -> 7 | F13: =DATA!G13 -> 44.27 | G13: =DATA!H13 -> 4.34 | H13: =DATA!E13 -> 3 | I13: =F13*E13 -> 309.89 | J13: =PARAMETER!$B$4*G13*SQRT(E13) -> 18.887132 | K13: =I13+J13 -> 328.77713 | L13: =K13+F13*H13 -> 461.58713 | M13: =IF(C13<=K13,"REORDER",IF(C13>L13,"OVERSTOCK","OK")) -> REORDER | N13: =IF(C13<=D13,"REORDER","OK") -> REORDER | O13: =IF(D13<I13,1,0) -> 1 | P13: =C13/F13 -> 0.45177321 | Q13: =DATA!N13 -> 35.51 | R13: =DATA!O13 -> 0.18 | S13: =C13*Q13 -> 710.2 | T13: =C13*R13 -> 3.6 | U13: =MAX(0,C13-L13) -> 0 | V13: =U13*Q13 -> 0 | W13: =U13*R13 -> 0 | X13: =MAX(0,K13-C13) -> 308.77713 | Y13: =F13*PARAMETER!$B$5*Q13 -> 573790.11 | Z13: =SUMIF($Y$2:$Y$3205,">="&Y13)/SUM($Y$2:$Y$3205) -> 0.88397221 | AA13: =IF(Z13<=PARAMETER!$B$7,"A",IF(Z13<=PARAMETER!$B$8,"B","C")) -> B | AB13: =G13/F13 -> 0.098034787 | AC13: =IF(AB13<=PARAMETER!$B$9,"X",IF(AB13<=PARAMETER!$B$10,"Y","Z")) -> X | AD13: =AA13&AC13 -> BX | AE13: =DATA!I13 -> 0.36 | AF13: =DATA!L13 -> 135 | AG13: =DATA!K13 -> A | AH13: =IF(AE13>=PARAMETER!$B$12,1,0) -> 0 | AI13: =IF(AF13>=PARAMETER!$B$13,1,0) -> 1 | AJ13: =IF(AND(AH13=1,AI13=1),1,0) -> 0
... A3205: =DATA!A3205 -> ITM13203 | B3205: =DATA!B3205 -> Apparel | C3205: =DATA!C3205 -> 377 | D3205: =DATA!D3205 -> 40 | E3205: =DATA!F3205 -> 3 | F3205: =DATA!G3205 -> 29.4 | G3205: =DATA!H3205 -> 7.43 | H3205: =DATA!E3205 -> 14 | I3205: =F3205*E3205 -> 88.2 | J3205: =PARAMETER!$B$4*G3205*SQRT(E3205) -> 21.167847 | K3205: =I3205+J3205 -> 109.36785 | L3205: =K3205+F3205*H3205 -> 520.96785 | M3205: =IF(C3205<=K3205,"REORDER",IF(C3205>L3205,"OVERSTOCK","OK")) -> OK | N3205: =IF(C3205<=D3205,"REORDER","OK") -> OK | O3205: =IF(D3205<I3205,1,0) -> 1 | P3205: =C3205/F3205 -> 12.823129 | Q3205: =DATA!N3205 -> 39.88 | R3205: =DATA!O3205 -> 1.94 | S3205: =C3205*Q3205 -> 15034.76 | T3205: =C3205*R3205 -> 731.38 | U3205: =MAX(0,C3205-L3205) -> 0 | V3205: =U3205*Q3205 -> 0 | W3205: =U3205*R3205 -> 0 | X3205: =MAX(0,K3205-C3205) -> 0 | Y3205: =F3205*PARAMETER!$B$5*Q3205 -> 427952.28 | Z3205: =SUMIF($Y$2:$Y$3205,">="&Y3205)/SUM($Y$2:$Y$3205) -> 0.92818038 | AA3205: =IF(Z3205<=PARAMETER!$B$7,"A",IF(Z3205<=PARAMETER!$B$8,"B","C")) -> B | AB3205: =G3205/F3205 -> 0.25272109 | AC3205: =IF(AB3205<=PARAMETER!$B$9,"X",IF(AB3205<=PARAMETER!$B$10,"Y","Z")) -> Y | AD3205: =AA3205&AC3205 -> BY | AE3205: =DATA!I3205 -> 0.14 | AF3205: =DATA!L3205 -> 56 | AG3205: =DATA!K3205 -> A | AH3205: =IF(AE3205>=PARAMETER!$B$12,1,0) -> 0 | AI3205: =IF(AF3205>=PARAMETER!$B$13,1,0) -> 0 | AJ3205: =IF(AND(AH3205=1,AI3205=1),1,0) -> 0

Sheet ANALYSIS
A1: Analisis
A2: Semua angka di sheet ini adalah rumus ke PROCESS/DATA.
A4: 1. Status stok: hitungan ulang vs versi dataset
A5: Status | B5: Hitung ulang | C5: % item | D5: Versi dataset | E5: % item
A6: REORDER | B6: =COUNTIF(PROCESS!$M$2:$M$3205,A6) -> 944 | C6: =B6/$B$9 -> 0.29463171 | D6: =COUNTIF(PROCESS!$N$2:$N$3205,A6) -> 240 | E6: =D6/$D$9 -> 0.074906367
A7: OK | B7: =COUNTIF(PROCESS!$M$2:$M$3205,A7) -> 1053 | C7: =B7/$B$9 -> 0.32865169 | D7: =COUNTIF(PROCESS!$N$2:$N$3205,A7) -> 2964 | E7: =D7/$D$9 -> 0.92509363
A8: OVERSTOCK | B8: =COUNTIF(PROCESS!$M$2:$M$3205,A8) -> 1207 | C8: =B8/$B$9 -> 0.3767166 | D8: =COUNTIF(PROCESS!$N$2:$N$3205,A8) -> 0 | E8: =D8/$D$9 -> 0
A9: Total | B9: =SUM(B6:B8) -> 3204 | C9: =SUM(C6:C8) -> 1 | D9: =SUM(D6:D8) -> 3204 | E9: =SUM(E6:E8) -> 1
A10: Item dengan ROP dataset < lead-time demand | B10: =SUM(PROCESS!$O$2:$O$3205) -> 2448 | C10: =B10/$B$9 -> 0.76404494
A11: Perlu reorder (hitung ulang) tapi dataset bilang OK | B11: =COUNTIFS(PROCESS!$M$2:$M$3205,"REORDER",PROCESS!$N$2:$N$3205,"OK") -> 727
A12: Korelasi ROP dataset vs ROP hitung | B12: =CORREL(PROCESS!$D$2:$D$3205,PROCESS!$K$2:$K$3205) -> -0.018285635
A13: Total kekurangan vs ROP (unit) | B13: =SUM(PROCESS!$X$2:$X$3205) -> 104606.96
A15: 2. Inventory cost
A16: Status | B16: Item | C16: Biaya simpan/hari | D16: % biaya simpan | E16: Nilai stok | F16: % nilai stok
A17: REORDER | B17: =B6 -> 944 | C17: =SUMIF(PROCESS!$M$2:$M$3205,A17,PROCESS!$T$2:$T$3205) -> 129821.03 | D17: =C17/$C$20 -> 0.14726516 | E17: =SUMIF(PROCESS!$M$2:$M$3205,A17,PROCESS!$S$2:$S$3205) -> 12894814 | F17: =E17/$E$20 -> 0.14396967
A18: OK | B18: =B7 -> 1053 | C18: =SUMIF(PROCESS!$M$2:$M$3205,A18,PROCESS!$T$2:$T$3205) -> 317386.34 | D18: =C18/$C$20 -> 0.36003374 | E18: =SUMIF(PROCESS!$M$2:$M$3205,A18,PROCESS!$S$2:$S$3205) -> 32720681 | F18: =E18/$E$20 -> 0.36532403
A19: OVERSTOCK | B19: =B8 -> 1207 | C19: =SUMIF(PROCESS!$M$2:$M$3205,A19,PROCESS!$T$2:$T$3205) -> 434338.74 | D19: =C19/$C$20 -> 0.4927011 | E19: =SUMIF(PROCESS!$M$2:$M$3205,A19,PROCESS!$S$2:$S$3205) -> 43950694 | F19: =E19/$E$20 -> 0.49070631
A20: Total | B20: =SUM(B17:B19) -> 3204 | C20: =SUM(C17:C19) -> 881546.11 | D20: =SUM(D17:D19) -> 1 | E20: =SUM(E17:E19) -> 89566189 | F20: =SUM(F17:F19) -> 1
A21: Biaya simpan per bulan | C21: =C20*PARAMETER!$B$6 -> 26446383
A22: Biaya simpan kelebihan stok/hari (potensi hemat) | C22: =SUM(PROCESS!$W$2:$W$3205) -> 199859.44 | D22: =C22/C20 -> 0.22671468
A23: Potensi hemat per bulan | C23: =C22*PARAMETER!$B$6 -> 5995783.3
A24: Nilai kelebihan stok | E24: =SUM(PROCESS!$V$2:$V$3205) -> 21082618 | F24: =E24/E20 -> 0.23538591
A26: Kategori | B26: Item | C26: Biaya simpan/hari | D26: Biaya kelebihan/hari | E26: % kelebihan | F26: Item overstock
A27: Apparel | B27: =COUNTIF(PROCESS!$B$2:$B$3205,A27) -> 617 | C27: =SUMIF(PROCESS!$B$2:$B$3205,A27,PROCESS!$T$2:$T$3205) -> 163883.23 | D27: =SUMIF(PROCESS!$B$2:$B$3205,A27,PROCESS!$W$2:$W$3205) -> 38105.504 | E27: =D27/C27 -> 0.23251619 | F27: =COUNTIFS(PROCESS!$B$2:$B$3205,A27,PROCESS!$M$2:$M$3205,"OVERSTOCK") -> 231
A28: Automotive | B28: =COUNTIF(PROCESS!$B$2:$B$3205,A28) -> 658 | C28: =SUMIF(PROCESS!$B$2:$B$3205,A28,PROCESS!$T$2:$T$3205) -> 176207.37 | D28: =SUMIF(PROCESS!$B$2:$B$3205,A28,PROCESS!$W$2:$W$3205) -> 37010.63 | E28: =D28/C28 -> 0.21004019 | F28: =COUNTIFS(PROCESS!$B$2:$B$3205,A28,PROCESS!$M$2:$M$3205,"OVERSTOCK") -> 240
A29: Electronics | B29: =COUNTIF(PROCESS!$B$2:$B$3205,A29) -> 651 | C29: =SUMIF(PROCESS!$B$2:$B$3205,A29,PROCESS!$T$2:$T$3205) -> 179893.41 | D29: =SUMIF(PROCESS!$B$2:$B$3205,A29,PROCESS!$W$2:$W$3205) -> 44881.028 | E29: =D29/C29 -> 0.24948678 | F29: =COUNTIFS(PROCESS!$B$2:$B$3205,A29,PROCESS!$M$2:$M$3205,"OVERSTOCK") -> 264
A30: Groceries | B30: =COUNTIF(PROCESS!$B$2:$B$3205,A30) -> 618 | C30: =SUMIF(PROCESS!$B$2:$B$3205,A30,PROCESS!$T$2:$T$3205) -> 177826.76 | D30: =SUMIF(PROCESS!$B$2:$B$3205,A30,PROCESS!$W$2:$W$3205) -> 37616.199 | E30: =D30/C30 -> 0.21153284 | F30: =COUNTIFS(PROCESS!$B$2:$B$3205,A30,PROCESS!$M$2:$M$3205,"OVERSTOCK") -> 228
A31: Pharma | B31: =COUNTIF(PROCESS!$B$2:$B$3205,A31) -> 660 | C31: =SUMIF(PROCESS!$B$2:$B$3205,A31,PROCESS!$T$2:$T$3205) -> 183735.34 | D31: =SUMIF(PROCESS!$B$2:$B$3205,A31,PROCESS!$W$2:$W$3205) -> 42246.08 | E31: =D31/C31 -> 0.22992899 | F31: =COUNTIFS(PROCESS!$B$2:$B$3205,A31,PROCESS!$M$2:$M$3205,"OVERSTOCK") -> 244
A33: 3. Trade-off service level vs biaya safety stock
A34: Service level | B34: z | C34: Safety stock (unit) | D34: Biaya SS/hari | E34: Kenaikan vs baris atas
A35: 0.9 | B35: =NORMSINV(A35) -> 1.2815516 | C35: =B35*SUMPRODUCT(DATA!$H$2:$H$3205,SQRT(DATA!$F$2:$F$3205)) -> 49744.76 | D35: =B35*SUMPRODUCT(DATA!$H$2:$H$3205,SQRT(DATA!$F$2:$F$3205),DATA!$O$2:$O$3205) -> 51616.861
A36: 0.95 | B36: =NORMSINV(A36) -> 1.6448536 | C36: =B36*SUMPRODUCT(DATA!$H$2:$H$3205,SQRT(DATA!$F$2:$F$3205)) -> 63846.708 | D36: =B36*SUMPRODUCT(DATA!$H$2:$H$3205,SQRT(DATA!$F$2:$F$3205),DATA!$O$2:$O$3205) -> 66249.523 | E36: =D36/D35-1 -> 0.2834861
A37: 0.99 | B37: =NORMSINV(A37) -> 2.3263479 | C37: =B37*SUMPRODUCT(DATA!$H$2:$H$3205,SQRT(DATA!$F$2:$F$3205)) -> 90299.618 | D37: =B37*SUMPRODUCT(DATA!$H$2:$H$3205,SQRT(DATA!$F$2:$F$3205),DATA!$O$2:$O$3205) -> 93697.965 | E37: =D37/D36-1 -> 0.41431908
A39: 4. Matriks ABC-XYZ (jumlah item)
A40: ABC \ XYZ | B40: X | C40: Y | D40: Z | E40: Total | F40: % nilai tahunan
A41: A | B41: =COUNTIFS(PROCESS!$AA$2:$AA$3205,$A41,PROCESS!$AC$2:$AC$3205,B$40) -> 1213 | C41: =COUNTIFS(PROCESS!$AA$2:$AA$3205,$A41,PROCESS!$AC$2:$AC$3205,C$40) -> 275 | D41: =COUNTIFS(PROCESS!$AA$2:$AA$3205,$A41,PROCESS!$AC$2:$AC$3205,D$40) -> 24 | E41: =SUM(B41:D41) -> 1512 | F41: =SUMIF(PROCESS!$AA$2:$AA$3205,A41,PROCESS!$Y$2:$Y$3205)/SUM(PROCESS!$Y$2:$Y$3205) -> 0.79976147
A42: B | B42: =COUNTIFS(PROCESS!$AA$2:$AA$3205,$A42,PROCESS!$AC$2:$AC$3205,B$40) -> 431 | C42: =COUNTIFS(PROCESS!$AA$2:$AA$3205,$A42,PROCESS!$AC$2:$AC$3205,C$40) -> 241 | D42: =COUNTIFS(PROCESS!$AA$2:$AA$3205,$A42,PROCESS!$AC$2:$AC$3205,D$40) -> 165 | E42: =SUM(B42:D42) -> 837 | F42: =SUMIF(PROCESS!$AA$2:$AA$3205,A42,PROCESS!$Y$2:$Y$3205)/SUM(PROCESS!$Y$2:$Y$3205) -> 0.1502241
A43: C | B43: =COUNTIFS(PROCESS!$AA$2:$AA$3205,$A43,PROCESS!$AC$2:$AC$3205,B$40) -> 256 | C43: =COUNTIFS(PROCESS!$AA$2:$AA$3205,$A43,PROCESS!$AC$2:$AC$3205,C$40) -> 178 | D43: =COUNTIFS(PROCESS!$AA$2:$AA$3205,$A43,PROCESS!$AC$2:$AC$3205,D$40) -> 421 | E43: =SUM(B43:D43) -> 855 | F43: =SUMIF(PROCESS!$AA$2:$AA$3205,A43,PROCESS!$Y$2:$Y$3205)/SUM(PROCESS!$Y$2:$Y$3205) -> 0.050014438
A44: Total | B44: =SUM(B41:B43) -> 1900 | C44: =SUM(C41:C43) -> 694 | D44: =SUM(D41:D43) -> 610 | E44: =SUM(E41:E43) -> 3204
A45: AX: nilai tinggi, demand stabil (replenishment rutin). AZ: nilai tinggi, tidak stabil (pantau paling ketat). CZ: nilai rendah, tidak stabil (stok minimum / pesan saat perlu).
...

Sheet DASHBOARD
A1: Warehouse Inventory Health Dashboard
A2: Logistics Warehouse Dataset (Kaggle, sintetis) | service level di PARAMETER
A4: Item dianalisis | C4: Perlu reorder | E4: Lolos dari radar dataset | G4: Overstock | I4: Biaya kelebihan stok | K4: Biaya SS 95%→99%
A5: =ANALYSIS!B9 -> 3204 | C5: =ANALYSIS!B6 -> 944 | E5: =ANALYSIS!B11 -> 727 | G5: =ANALYSIS!B8 -> 1207 | I5: =ANALYSIS!D22 -> 0.22671468 | K5: =ANALYSIS!E37 -> 0.41431908

Sheet INSIGHT
B2: Insight & rekomendasi
B3: Angka di bawah dihitung otomatis dari ANALYSIS.
B5: Reorder point bawaan dataset tidak bisa dipakai
B6: ="Di "&TEXT(ANALYSIS!C10,"0%")&" item, ROP dataset lebih kecil dari kebutuhan selama lead time, dan tidak berkorelasi dengan ROP hasil hitung (r = "&TEXT(ANALYSIS!B12,"0.00")&")." -> Di 76% item, ROP dataset lebih kecil dari kebutuhan selama lead time, dan tidak berkorelasi dengan ROP hasil hitung (r = -0.02).
B8: Banyak item yang seharusnya dipesan terlewat
B9: ="Dengan ROP plus safety stock, "&TEXT(ANALYSIS!B6,"#,##0")&" item ("&TEXT(ANALYSIS!C6,"0.0%")&") perlu reorder. Versi dataset hanya menandai "&TEXT(ANALYSIS!D6,"#,##0")&", sehingga "&TEXT(ANALYSIS!B11,"#,##0")&" item yang perlu dipesan dianggap aman." -> Dengan ROP plus safety stock, 944 item (29.5%) perlu reorder. Versi dataset hanya menandai 240, sehingga 727 item yang perlu dipesan dianggap aman.
B11: Overstock menyedot biaya simpan
B12: =TEXT(ANALYSIS!B8,"#,##0")&" item overstock ("&TEXT(ANALYSIS!C8,"0.0%")&" item) menanggung "&TEXT(ANALYSIS!D19,"0.0%")&" biaya simpan. Menurunkan stoknya ke level maksimum menghemat "&TEXT(ANALYSIS!D22,"0.0%")&" biaya simpan harian." -> 1,207 item overstock (37.7% item) menanggung 49.3% biaya simpan. Menurunkan stoknya ke level maksimum menghemat 22.7% biaya simpan harian.
B14: Service level tinggi makin mahal
B15: ="Biaya safety stock naik "&TEXT(ANALYSIS!E36,"0.0%")&" dari 90% ke 95%, lalu naik "&TEXT(ANALYSIS!E37,"0.0%")&" lagi dari 95% ke 99%. Target 99% sebaiknya hanya untuk item kelas A." -> Biaya safety stock naik 28.3% dari 90% ke 95%, lalu naik 41.4% lagi dari 95% ke 99%. Target 99% sebaiknya hanya untuk item kelas A.
B17: Kebijakan stok per kelompok ABC-XYZ
B18: ="AX ("&TEXT(ANALYSIS!B41,"#,##0")&" item): replenishment rutin dengan stok pengaman kecil. AZ ("&TEXT(ANALYSIS!D41,"#,##0")&" item): pantau paling ketat. CZ ("&TEXT(ANALYSIS!D43,"#,##0")&" item): stok minimum atau pesan saat dibutuhkan." -> AX (1,213 item): replenishment rutin dengan stok pengaman kecil. AZ (24 item): pantau paling ketat. CZ (421 item): stok minimum atau pesan saat dibutuhkan.
B20: Penempatan barang belum mengikuti popularitas
B21: ="Korelasi popularitas dengan picking time hanya "&TEXT(ANALYSIS!B48,"0.00")&". "&TEXT(ANALYSIS!B50,"#,##0")&" dari "&TEXT(ANALYSIS!B49,"#,##0")&" item paling populer ada di lokasi picking lambat dan bisa dipindah ke lokasi yang lebih cepat." -> Korelasi popularitas dengan picking time hanya 0.01. 422 dari 839 item paling populer ada di lokasi picking lambat dan bisa dipindah ke lokasi yang lebih cepat.
B23: Catatan data
B24: Dataset sintetis dari Kaggle. Hasil ini menunjukkan metode perencanaan persediaan yang bisa diterapkan ke data perusahaan nyata.
